Workbook

Sheet Sheet1
A1: Unnamed: 0 | B1: Train | C1: Prev_Block | D1: Prev_Block_Line | E1: Station_Sequence | F1: Station | G1: Station_Line | H1: Next_Block | I1: Next_Block_Line | J1: Entry_Time | K1: Exit_Time | L1: Block_Exit_Time | M1: Cumulative_Distance
A2: 1781 | B2: 12021_0 | C2: Not_Defined | D2: Not_Defined | E2: =IF(B1920=B1919,E1919+1,1) -> 1 | F2: HWH | G2: 7 | H2: HWH-TPKR | I2: 1 | J2: 22278 | K2: 22278 | L2: =IF(AND(H1920=C1921,B1920=B1921),J1921,"") -> 22782 | M2: =VLOOKUP(F1920,Sheet2!$A$2:$B$500,2,FALSE) -> 0
A3: 1782 | B3: 12021_0 | C3: HWH-TPKR | D3: 1 | E3: =IF(B1921=B1920,E1920+1,1) -> 2 | F3: TPKR | G3: 2 | H3: TPKR-DSNR | I3: 2 | J3: 22782 | K3: 22782 | L3: =IF(AND(H1921=C1922,B1921=B1922),J1922,"") -> 22948 | M3: =VLOOKUP(F1921,Sheet2!$A$2:$B$500,2,FALSE) -> 2.7
A4: 1783 | B4: 12021_0 | C4: TPKR-DSNR | D4: 2 | E4: =IF(B1922=B1921,E1921+1,1) -> 3 | F4: DSNR | G4: 2 | H4: DSNR-RMJ | I4: 2 | J4: 22948 | K4: 22948 | L4: =IF(AND(H1922=C1923,B1922=B1923),J1923,"") -> 23082 | M4: =VLOOKUP(F1922,Sheet2!$A$2:$B$500,2,FALSE) -> 4.44
A5: 1784 | B5: 12021_0 | C5: DSNR-RMJ | D5: 2 | E5: =IF(B1923=B1922,E1922+1,1) -> 4 | F5: RMJ | G5: 2 | H5: RMJ-SRC | I5: 2 | J5: 23082 | K5: 23082 | L5: =IF(AND(H1923=C1924,B1923=B1924),J1924,"") -> 23244 | M5: =VLOOKUP(F1923,Sheet2!$A$2:$B$500,2,FALSE) -> 6.08
A6: 1785 | B6: 12021_0 | C6: RMJ-SRC | D6: 2 | E6: =IF(B1924=B1923,E1923+1,1) -> 5 | F6: SRC | G6: 2 | H6: SRC-MRGM | I6: 1 | J6: 23244 | K6: 23244 | L6: =IF(AND(H1924=C1925,B1924=B1925),J1925,"") -> 23360 | M6: =VLOOKUP(F1924,Sheet2!$A$2:$B$500,2,FALSE) -> 7.48
A7: 1786 | B7: 12021_0 | C7: SRC-MRGM | D7: 1 | E7: =IF(B1925=B1924,E1924+1,1) -> 6 | F7: MRGM | G7: 1 | H7: MRGM-ADL | I7: 1 | J7: 23360 | K7: 23360 | L7: =IF(AND(H1925=C1926,B1925=B1926),J1926,"") -> 23438 | M7: =VLOOKUP(F1925,Sheet2!$A$2:$B$500,2,FALSE) -> 10.3
A8: 1787 | B8: 12021_0 | C8: MRGM-ADL | D8: 1 | E8: =IF(B1926=B1925,E1925+1,1) -> 7 | F8: ADL | G8: 1 | H8: ADL-SEL | I8: 2 | J8: 23438 | K8: 23438 | L8: =IF(AND(H1926=C1927,B1926=B1927),J1927,"") -> 23592 | M8: =VLOOKUP(F1926,Sheet2!$A$2:$B$500,2,FALSE) -> 12.3
A9: 1788 | B9: 12021_0 | C9: ADL-SEL | D9: 2 | E9: =IF(B1927=B1926,E1926+1,1) -> 8 | F9: SEL | G9: 2 | H9: SEL-ABB | I9: 1 | J9: 23592 | K9: 23592 | L9: =IF(AND(H1927=C1928,B1927=B1928),J1928,"") -> 23664 | M9: =VLOOKUP(F1927,Sheet2!$A$2:$B$500,2,FALSE) -> 15.9
A10: 1789 | B10: 12021_0 | C10: SEL-ABB | D10: 1 | E10: =IF(B1928=B1927,E1927+1,1) -> 9 | F10: ABB | G10: 2 | H10: ABB-NALR | I10: 2 | J10: 23664 | K10: 23664 | L10: =IF(AND(H1928=C1929,B1928=B1929),J1929,"") -> 23782 | M10: =VLOOKUP(F1928,Sheet2!$A$2:$B$500,2,FALSE) -> 17.2
A11: 1790 | B11: 12021_0 | C11: ABB-NALR | D11: 2 | E11: =IF(B1929=B1928,E1928+1,1) -> 10 | F11: NALR | G11: 2 | H11: NALR-BVA | I11: 2 | J11: 23782 | K11: 23782 | L11: =IF(AND(H1929=C1930,B1929=B1930),J1930,"") -> 23938 | M11: =VLOOKUP(F1929,Sheet2!$A$2:$B$500,2,FALSE) -> 20.2
A12: 1791 | B12: 12021_0 | C12: NALR-BVA | D12: 2 | E12: =IF(B1930=B1929,E1929+1,1) -> 11 | F12: BVA | G12: 1 | H12: BVA-CGA | I12: 1 | J12: 23938 | K12: 23938 | L12: =IF(AND(H1930=C1931,B1930=B1931),J1931,"") -> 24148 | M12: =VLOOKUP(F1930,Sheet2!$A$2:$B$500,2,FALSE) -> 24.1
A13: 1792 | B13: 12021_0 | C13: BVA-CGA | D13: 1 | E13: =IF(B1931=B1930,E1930+1,1) -> 12 | F13: CGA | G13: 1 | H13: CGA-FLR | I13: 1 | J13: 24148 | K13: 24148 | L13: =IF(AND(H1931=C1932,B1931=B1932),J1932,"") -> 24232 | M13: =VLOOKUP(F1931,Sheet2!$A$2:$B$500,2,FALSE) -> 27.24
A14: 1793 | B14: 12021_0 | C14: CGA-FLR | D14: 1 | E14: =IF(B1932=B1931,E1931+1,1) -> 13 | F14: FLR | G14: 1 | H14: FLR-ULB | I14: 1 | J14: 24232 | K14: 24232 | L14: =IF(AND(H1932=C1933,B1932=B1933),J1933,"") -> 24404 | M14: =VLOOKUP(F1932,Sheet2!$A$2:$B$500,2,FALSE) -> 29.84
... A62: 1841 | B62: 12021_0 | C62: MMV-RKSN | D62: 2 | E62: =IF(B1980=B1979,E1979+1,1) -> 61 | F62: RKSN | G62: 8 | H62: RKSN-RKWO | I62: 2 | J62: 36662 | K62: 36662 | L62: =IF(AND(H1980=C1981,B1980=B1981),J1981,"") -> 36800 | M62: =VLOOKUP(F1980,Sheet2!$A$2:$B$500,2,FALSE) -> 292.25
A63: 1842 | B63: 12021_0 | C63: RKSN-RKWO | D63: 2 | E63: =IF(B1981=B1980,E1980+1,1) -> 62 | F63: RKWO | G63: 2 | J63: 36800 | K63: 36800 | L63: =IF(AND(H1981=C1982,B1981=B1982),J1982,"") | M63: =VLOOKUP(F1981,Sheet2!$A$2:$B$500,2,FALSE) -> 294.17
A64: 5737 | B64: 12021_1 | C64: Not_Defined | D64: Not_Defined | E64: =IF(B1982=B1981,E1981+1,1) -> 1 | F64: HWH | G64: 7 | H64: HWH-TPKR | I64: 2 | J64: 108678 | K64: 108678 | L64: =IF(AND(H1982=C1983,B1982=B1983),J1983,"") -> 109182 | M64: =VLOOKUP(F1982,Sheet2!$A$2:$B$500,2,FALSE) -> 0
A65: 5738 | B65: 12021_1 | C65: HWH-TPKR | D65: 2 | E65: =IF(B1983=B1982,E1982+1,1) -> 2 | F65: TPKR | G65: 3 | H65: TPKR-DSNR | I65: 3 | J65: 109182 | K65: 109182 | L65: =IF(AND(H1983=C1984,B1983=B1984),J1984,"") -> 109348 | M65: =VLOOKUP(F1983,Sheet2!$A$2:$B$500,2,FALSE) -> 2.7
A66: 5739 | B66: 12021_1 | C66: TPKR-DSNR | D66: 3 | E66: =IF(B1984=B1983,E1983+1,1) -> 3 | F66: DSNR | G66: 3 | H66: DSNR-RMJ | I66: 3 | J66: 109348 | K66: 109348 | L66: =IF(AND(H1984=C1985,B1984=B1985),J1985,"") -> 109482 | M66: =VLOOKUP(F1984,Sheet2!$A$2:$B$500,2,FALSE) -> 4.44
A67: 5740 | B67: 12021_1 | C67: DSNR-RMJ | D67: 3 | E67: =IF(B1985=B1984,E1984+1,1) -> 4 | F67: RMJ | G67: 3 | H67: RMJ-SRC | I67: 3 | J67: 109482 | K67: 109482 | L67: =IF(AND(H1985=C1986,B1985=B1986),J1986,"") -> 109644 | M67: =VLOOKUP(F1985,Sheet2!$A$2:$B$500,2,FALSE) -> 6.08
A68: 5741 | B68: 12021_1 | C68: RMJ-SRC | D68: 3 | E68: =IF(B1986=B1985,E1985+1,1) -> 5 | F68: SRC | G68: 4 | H68: SRC-MRGM | I68: 1 | J68: 109644 | K68: 109644 | L68: =IF(AND(H1986=C1987,B1986=B1987),J1987,"") -> 109760 | M68: =VLOOKUP(F1986,Sheet2!$A$2:$B$500,2,FALSE) -> 7.48
A69: 5742 | B69: 12021_1 | C69: SRC-MRGM | D69: 1 | E69: =IF(B1987=B1986,E1986+1,1) -> 6 | F69: MRGM | G69: 1 | H69: MRGM-ADL | I69: 1 | J69: 109760 | K69: 109760 | L69: =IF(AND(H1987=C1988,B1987=B1988),J1988,"") -> 109838 | M69: =VLOOKUP(F1987,Sheet2!$A$2:$B$500,2,FALSE) -> 10.3
A70: 5743 | B70: 12021_1 | C70: MRGM-ADL | D70: 1 | E70: =IF(B1988=B1987,E1987+1,1) -> 7 | F70: ADL | G70: 1 | H70: ADL-SEL | I70: 2 | J70: 109838 | K70: 109838 | L70: =IF(AND(H1988=C1989,B1988=B1989),J1989,"") -> 109992 | M70: =VLOOKUP(F1988,Sheet2!$A$2:$B$500,2,FALSE) -> 12.3
A71: 5744 | B71: 12021_1 | C71: ADL-SEL | D71: 2 | E71: =IF(B1989=B1988,E1988+1,1) -> 8 | F71: SEL | G71: 2 | H71: SEL-ABB | I71: 2 | J71: 109992 | K71: 109992 | L71: =IF(AND(H1989=C1990,B1989=B1990),J1990,"") -> 110064 | M71: =VLOOKUP(F1989,Sheet2!$A$2:$B$500,2,FALSE) -> 15.9
A72: 5745 | B72: 12021_1 | C72: SEL-ABB | D72: 2 | E72: =IF(B1990=B1989,E1989+1,1) -> 9 | F72: ABB | G72: 2 | H72: ABB-NALR | I72: 2 | J72: 110064 | K72: 110064 | L72: =IF(AND(H1990=C1991,B1990=B1991),J1991,"") -> 110182 | M72: =VLOOKUP(F1990,Sheet2!$A$2:$B$500,2,FALSE) -> 17.2
A73: 5746 | B73: 12021_1 | C73: ABB-NALR | D73: 2 | E73: =IF(B1991=B1990,E1990+1,1) -> 10 | F73: NALR | G73: 2 | H73: NALR-BVA | I73: 2 | J73: 110182 | K73: 110182 | L73: =IF(AND(H1991=C1992,B1991=B1992),J1992,"") -> 110338 | M73: =VLOOKUP(F1991,Sheet2!$A$2:$B$500,2,FALSE) -> 20.2
A74: 5747 | B74: 12021_1 | C74: NALR-BVA | D74: 2 | E74: =IF(B1992=B1991,E1991+1,1) -> 11 | F74: BVA | G74: 1 | H74: BVA-CGA | I74: 1 | J74: 110338 | K74: 110338 | L74: =IF(AND(H1992=C1993,B1992=B1993),J1993,"") -> 110548 | M74: =VLOOKUP(F1992,Sheet2!$A$2:$B$500,2,FALSE) -> 24.1
A75: 5748 | B75: 12021_1 | C75: BVA-CGA | D75: 1 | E75: =IF(B1993=B1992,E1992+1,1) -> 12 | F75: CGA | G75: 1 | H75: CGA-FLR | I75: 1 | J75: 110548 | K75: 110548 | L75: =IF(AND(H1993=C1994,B1993=B1994),J1994,"") -> 110632 | M75: =VLOOKUP(F1993,Sheet2!$A$2:$B$500,2,FALSE) -> 27.24
A76: 5749 | B76: 12021_1 | C76: CGA-FLR | D76: 1 | E76: =IF(B1994=B1993,E1993+1,1) -> 13 | F76: FLR | G76: 1 | H76: FLR-ULB | I76: 1 | J76: 110632 | K76: 110632 | L76: =IF(AND(H1994=C1995,B1994=B1995),J1995,"") -> 110804 | M76: =VLOOKUP(F1994,Sheet2!$A$2:$B$500,2,FALSE) -> 29.84
... A124: 5797 | B124: 12021_1 | C124: MMV-RKSN | D124: 2 | E124: =IF(B2042=B2041,E2041+1,1) -> 61 | F124: RKSN | G124: 9 | H124: RKSN-RKWO | I124: 3 | J124: 123062 | K124: 123062 | L124: =IF(AND(H2042=C2043,B2042=B2043),J2043,"") -> 123200 | M124: =VLOOKUP(F2042,Sheet2!$A$2:$B$500,2,FALSE) -> 292.25
A125: 5798 | B125: 12021_1 | C125: RKSN-RKWO | D125: 3 | E125: =IF(B2043=B2042,E2042+1,1) -> 62 | F125: RKWO | G125: 3 | J125: 123200 | K125: 123200 | L125: =IF(AND(H2043=C2044,B2043=B2044),J2044,"") | M125: =VLOOKUP(F2043,Sheet2!$A$2:$B$500,2,FALSE) -> 294.17
A126: 1525 | B126: 12022_0 | C126: Not_Defined | D126: Not_Defined | E126: =IF(B2044=B2043,E2043+1,1) -> 1 | F126: RKSN | G126: 1 | H126: RKSN-MMV | I126: 1 | J126: 57060 | K126: 57060 | L126: =IF(AND(H2044=C2045,B2044=B2045),J2045,"") -> 57340 | M126: =VLOOKUP(F2044,Sheet2!$A$2:$B$500,2,FALSE) -> 292.25
A127: 1526 | B127: 12022_0 | C127: RKSN-MMV | D127: 1 | E127: =IF(B2045=B2044,E2044+1,1) -> 2 | F127: MMV | G127: 1 | H127: MMV-SINI | I127: 1 | J127: 57340 | K127: 57340 | L127: =IF(AND(H2045=C2046,B2045=B2046),J2046,"") -> 57624 | M127: =VLOOKUP(F2045,Sheet2!$A$2:$B$500,2,FALSE) -> 284.85
A128: 1527 | B128: 12022_0 | C128: MMV-SINI | D128: 1 | E128: =IF(B2046=B2045,E2045+1,1) -> 3 | F128: SINI | G128: 5 | H128: SINI-BRBS | I128: 3 | J128: 57624 | K128: 57744 | L128: =IF(AND(H2046=C2047,B2046=B2047),J2047,"") -> 58022 | M128: =VLOOKUP(F2046,Sheet2!$A$2:$B$500,2,FALSE) -> 277.05
A129: 1528 | B129: 12022_0 | C129: SINI-BRBS | D129: 3 | E129: =IF(B2047=B2046,E2046+1,1) -> 4 | F129: BRBS | G129: 3 | H129: BRBS-GMH | I129: 3 | J129: 58022 | K129: 58022 | L129: =IF(AND(H2047=C2048,B2047=B2048),J2048,"") -> 58382 | M129: =VLOOKUP(F2047,Sheet2!$A$2:$B$500,2,FALSE) -> 269.89
A130: 1529 | B130: 12022_0 | C130: BRBS-GMH | D130: 3 | E130: =IF(B2048=B2047,E2047+1,1) -> 5 | F130: GMH | G130: 6 | H130: GMH-ADTP | I130: 3 | J130: 58382 | K130: 58382 | L130: =IF(AND(H2048=C2049,B2048=B2049),J2049,"") -> 58680 | M130: =VLOOKUP(F2048,Sheet2!$A$2:$B$500,2,FALSE) -> 260.81
A131: 1530 | B131: 12022_0 | C131: GMH-ADTP | D131: 3 | E131: =IF(B2049=B2048,E2048+1,1) -> 6 | F131: ADTP | G131: 1 | H131: ADTP-TATA | I131: 1 | J131: 58680 | K131: 58680 | L131: =IF(AND(H2049=C2050,B2049=B2050),J2050,"") -> 59022 | M131: =VLOOKUP(F2049,Sheet2!$A$2:$B$500,2,FALSE) -> 254.61
A132: 1531 | B132: 12022_0 | C132: ADTP-TATA | D132: 1 | E132: =IF(B2050=B2049,E2049+1,1) -> 7 | F132: TATA | G132: 6 | H132: TATA-SLJR | I132: 2 | J132: 59022 | K132: 59502 | L132: =IF(AND(H2050=C2051,B2050=B2051),J2051,"") -> 59740 | M132: =VLOOKUP(F2050,Sheet2!$A$2:$B$500,2,FALSE) -> 250.21
A133: 1532 | B133: 12022_0 | C133: TATA-SLJR | D133: 2 | E133: =IF(B2051=B2050,E2050+1,1) -> 8 | F133: SLJR | G133: 2 | H133: SLJR-GVDP | I133: 2 | J133: 59740 | K133: 59740 | L133: =IF(AND(H2051=C2052,B2051=B2052),J2052,"") -> 59868 | M133: =VLOOKUP(F2051,Sheet2!$A$2:$B$500,2,FALSE) -> 247.11
A134: 1533 | B134: 12022_0 | C134: SLJR-GVDP | D134: 2 | E134: =IF(B2052=B2051,E2051+1,1) -> 9 | F134: GVDP | G134: 2 | H134: GVDP-ASB | I134: 2 | J134: 59868 | K134: 59868 | L134: =IF(AND(H2052=C2053,B2052=B2053),J2053,"") -> 60258 | M134: =VLOOKUP(F2052,Sheet2!$A$2:$B$500,2,FALSE) -> 243.13
...

Sheet Sheet2
A1: Station | B1: Distance
A2: HWH | B2: 0
A3: TPKR | B3: 2.7
A4: DSNR | B4: 4.44
A5: RMJ | B5: 6.08
A6: SRC | B6: 7.48
A7: MRGM | B7: 10.3
A8: ADL | B8: 12.3
A9: SEL | B9: 15.9
A10: ABB | B10: 17.2
A11: NALR | B11: 20.2
A12: BVA | B12: 24.1
A13: CGA | B13: 27.24
... A319: CABN | B319: 844
